<?xml version="1.0" ?>
<!-- =================================================================================== -->
<!-- |    This document was autogenerated by xacro from (Unsaved).xacro                | -->
<!-- |    EDITING THIS FILE BY HAND IS NOT RECOMMENDED                                 | -->
<!-- =================================================================================== -->
<robot name="(Unsaved)">
  <material name="silver">
    <color rgba="0.700 0.700 0.700 1.000"/>
  </material>
  <link name="base_link">
    <inertial>
      <origin rpy="0 0 0" xyz="-0.19747326793103112 0.0011545818939354344 0.001999156859975229"/>
      <mass value="1.0602977360982548"/>
      <inertia ixx="0.005088" ixy="1.5e-05" ixz="0.0" iyy="0.002124" iyz="1e-06" izz="0.007209"/>
    </inertial>
    <visual>
      <origin rpy="0 0 0" xyz="0 0 0"/>
      <geometry>
        <mesh filename="base_link.stl" scale="0.001 0.001 0.001"/>
      </geometry>
      <material name="silver"/>
    </visual>
    <collision>
      <origin rpy="0 0 0" xyz="0 0 0"/>
      <geometry>
        <mesh filename="base_link.stl" scale="0.001 0.001 0.001"/>
      </geometry>
    </collision>
  </link>
  <link name="teta1_1">
    <inertial>
      <origin rpy="0 0 0" xyz="0.030534126789324406 -0.015667414362937795 -0.00029693086440870514"/>
      <mass value="0.322485513471676"/>
      <inertia ixx="7.5e-05" ixy="2e-06" ixz="0.0" iyy="7.3e-05" iyz="-0.0" izz="9.9e-05"/>
    </inertial>
    <visual>
      <origin rpy="0 0 0" xyz="0.144694 0.105026 0.0515"/>
      <geometry>
        <mesh filename="teta1_1.stl" scale="0.001 0.001 0.001"/>
      </geometry>
      <material name="silver"/>
    </visual>
    <collision>
      <origin rpy="0 0 0" xyz="0.144694 0.105026 0.0515"/>
      <geometry>
        <mesh filename="teta1_1.stl" scale="0.001 0.001 0.001"/>
      </geometry>
    </collision>
  </link>
  <link name="tibia1_1">
    <inertial>
      <origin rpy="0 0 0" xyz="0.013631914546237855 0.009229301543740576 -0.01387288396315086"/>
      <mass value="0.5005531081408956"/>
      <inertia ixx="0.000169" ixy="4e-06" ixz="0.0" iyy="0.000166" iyz="0.0" izz="0.000101"/>
    </inertial>
    <visual>
      <origin rpy="0 0 0" xyz="0.111055 0.154709 0.0515"/>
      <geometry>
        <mesh filename="tibia1_1.stl" scale="0.001 0.001 0.001"/>
      </geometry>
      <material name="silver"/>
    </visual>
    <collision>
      <origin rpy="0 0 0" xyz="0.111055 0.154709 0.0515"/>
      <geometry>
        <mesh filename="tibia1_1.stl" scale="0.001 0.001 0.001"/>
      </geometry>
    </collision>
  </link>
  <link name="teta2_1">
    <inertial>
      <origin rpy="0 0 0" xyz="0.030092369962315096 0.016499999999999838 -0.00029693086440886474"/>
      <mass value="0.322485513471676"/>
      <inertia ixx="7.1e-05" ixy="-0.0" ixz="0.0" iyy="7.6e-05" iyz="-0.0" izz="9.9e-05"/>
    </inertial>
    <visual>
      <origin rpy="0 0 0" xyz="0.105851 0.0165 0.0515"/>
      <geometry>
        <mesh filename="teta2_1.stl" scale="0.001 0.001 0.001"/>
      </geometry>
      <material name="silver"/>
    </visual>
    <collision>
      <origin rpy="0 0 0" xyz="0.105851 0.0165 0.0515"/>
      <geometry>
        <mesh filename="teta2_1.stl" scale="0.001 0.001 0.001"/>
      </geometry>
    </collision>
  </link>
  <link name="tibia2_1">
    <inertial>
      <origin rpy="0 0 0" xyz="2.0452293353345752e-07 0.01646291267745646 -0.013872883963150555"/>
      <mass value="0.5005531081408956"/>
      <inertia ixx="0.000163" ixy="0.0" ixz="-0.0" iyy="0.000172" iyz="0.0" izz="0.000101"/>
    </inertial>
    <visual>
      <origin rpy="0 0 0" xyz="0.045851 0.0165 0.0515"/>
      <geometry>
        <mesh filename="tibia2_1.stl" scale="0.001 0.001 0.001"/>
      </geometry>
      <material name="silver"/>
    </visual>
    <collision>
      <origin rpy="0 0 0" xyz="0.045851 0.0165 0.0515"/>
      <geometry>
        <mesh filename="tibia2_1.stl" scale="0.001 0.001 0.001"/>
      </geometry>
    </collision>
  </link>
  <link name="teta3_1">
    <inertial>
      <origin rpy="0 0 0" xyz="0.0049988335991379 0.03378988634228103 0.0002969308644092117"/>
      <mass value="0.322485513471676"/>
      <inertia ixx="7.4e-05" ixy="-2e-06" ixz="0.0" iyy="7.3e-05" iyz="0.0" izz="9.9e-05"/>
    </inertial>
    <visual>
      <origin rpy="0 0 0" xyz="0.115797 -0.084261 0.0515"/>
      <geometry>
        <mesh filename="teta3_1.stl" scale="0.001 0.001 0.001"/>
      </geometry>
      <material name="silver"/>
    </visual>
    <collision>
      <origin rpy="0 0 0" xyz="0.115797 -0.084261 0.0515"/>
      <geometry>
        <mesh filename="teta3_1.stl" scale="0.001 0.001 0.001"/>
      </geometry>
    </collision>
  </link>
  <link name="tibia3_1">
    <inertial>
      <origin rpy="0 0 0" xyz="-0.01309616122417527 0.009975931443530317 -0.013872883963150652"/>
      <mass value="0.5005531081408956"/>
      <inertia ixx="0.000169" ixy="-4e-06" ixz="-0.0" iyy="0.000166" iyz="0.0" izz="0.000101"/>
    </inertial>
    <visual>
      <origin rpy="0 0 0" xyz="0.079437 -0.13199 0.0515"/>
      <geometry>
        <mesh filename="tibia3_1.stl" scale="0.001 0.001 0.001"/>
      </geometry>
      <material name="silver"/>
    </visual>
    <collision>
      <origin rpy="0 0 0" xyz="0.079437 -0.13199 0.0515"/>
      <geometry>
        <mesh filename="tibia3_1.stl" scale="0.001 0.001 0.001"/>
      </geometry>
    </collision>
  </link>
  <link name="teta4_1">
    <inertial>
      <origin rpy="0 0 0" xyz="-0.031894846797939025 0.012668757983660323 -0.00029693086440856636"/>
      <mass value="0.322485513471676"/>
      <inertia ixx="7.4e-05" ixy="3e-06" ixz="-0.0" iyy="7.3e-05" iyz="0.0" izz="9.9e-05"/>
    </inertial>
    <visual>
      <origin rpy="0 0 0" xyz="0.254528 -0.103617 0.0515"/>
      <geometry>
        <mesh filename="teta4_1.stl" scale="0.001 0.001 0.001"/>
      </geometry>
      <material name="silver"/>
    </visual>
    <collision>
      <origin rpy="0 0 0" xyz="0.254528 -0.103617 0.0515"/>
      <geometry>
        <mesh filename="teta4_1.stl" scale="0.001 0.001 0.001"/>
      </geometry>
    </collision>
  </link>
  <link name="tibia4_1">
    <inertial>
      <origin rpy="0 0 0" xyz="-0.01268524175515362 -0.010494219075531164 -0.013872883963149903"/>
      <mass value="0.5005531081408956"/>
      <inertia ixx="0.000168" ixy="4e-06" ixz="-0.0" iyy="0.000167" iyz="-0.0" izz="0.000101"/>
    </inertial>
    <visual>
      <origin rpy="0 0 0" xyz="0.292773 -0.149848 0.0515"/>
      <geometry>
        <mesh filename="tibia4_1.stl" scale="0.001 0.001 0.001"/>
      </geometry>
      <material name="silver"/>
    </visual>
    <collision>
      <origin rpy="0 0 0" xyz="0.292773 -0.149848 0.0515"/>
      <geometry>
        <mesh filename="tibia4_1.stl" scale="0.001 0.001 0.001"/>
      </geometry>
    </collision>
  </link>
  <link name="teta5_1">
    <inertial>
      <origin rpy="0 0 0" xyz="-0.03009196091642463 -0.016500000000000042 -0.00029693086440888555"/>
      <mass value="0.322485513471676"/>
      <inertia ixx="7.1e-05" ixy="-0.0" ixz="-0.0" iyy="7.6e-05" iyz="-0.0" izz="9.9e-05"/>
    </inertial>
    <visual>
      <origin rpy="0 0 0" xyz="0.288851 -0.0165 0.0515"/>
      <geometry>
        <mesh filename="teta5_1.stl" scale="0.001 0.001 0.001"/>
      </geometry>
      <material name="silver"/>
    </visual>
    <collision>
      <origin rpy="0 0 0" xyz="0.288851 -0.0165 0.0515"/>
      <geometry>
        <mesh filename="teta5_1.stl" scale="0.001 0.001 0.001"/>
      </geometry>
    </collision>
  </link>
  <link name="tibia5_1">
    <inertial>
      <origin rpy="0 0 0" xyz="2.0452295651507413e-07 -0.01646291267745669 -0.013872883963150527"/>
      <mass value="0.5005531081408956"/>
      <inertia ixx="0.000163" ixy="0.0" ixz="0.0" iyy="0.000172" iyz="-0.0" izz="0.000101"/>
    </inertial>
    <visual>
      <origin rpy="0 0 0" xyz="0.348851 -0.0165 0.0515"/>
      <geometry>
        <mesh filename="tibia5_1.stl" scale="0.001 0.001 0.001"/>
      </geometry>
      <material name="silver"/>
    </visual>
    <collision>
      <origin rpy="0 0 0" xyz="0.348851 -0.0165 0.0515"/>
      <geometry>
        <mesh filename="tibia5_1.stl" scale="0.001 0.001 0.001"/>
      </geometry>
    </collision>
  </link>
  <link name="teta6_1">
    <inertial>
      <origin rpy="0 0 0" xyz="-0.004160848120962735 -0.034065716062035664 -0.00029693086440885086"/>
      <mass value="0.322485513471676"/>
      <inertia ixx="7.5e-05" ixy="-2e-06" ixz="-0.0" iyy="7.3e-05" iyz="-0.0" izz="9.9e-05"/>
    </inertial>
    <visual>
      <origin rpy="0 0 0" xyz="0.278135 0.085404 0.0515"/>
      <geometry>
        <mesh filename="teta6_1.stl" scale="0.001 0.001 0.001"/>
      </geometry>
      <material name="silver"/>
    </visual>
    <collision>
      <origin rpy="0 0 0" xyz="0.278135 0.085404 0.0515"/>
      <geometry>
        <mesh filename="teta6_1.stl" scale="0.001 0.001 0.001"/>
      </geometry>
    </collision>
  </link>
  <link name="tibia6_1">
    <inertial>
      <origin rpy="0 0 0" xyz="0.013369579866801706 -0.009606733852596305 -0.013872883963150888"/>
      <mass value="0.5005531081408956"/>
      <inertia ixx="0.000169" ixy="-4e-06" ixz="0.0" iyy="0.000166" iyz="-0.0" izz="0.000101"/>
    </inertial>
    <visual>
      <origin rpy="0 0 0" xyz="0.313148 0.134129 0.0515"/>
      <geometry>
        <mesh filename="tibia6_1.stl" scale="0.001 0.001 0.001"/>
      </geometry>
      <material name="silver"/>
    </visual>
    <collision>
      <origin rpy="0 0 0" xyz="0.313148 0.134129 0.0515"/>
      <geometry>
        <mesh filename="tibia6_1.stl" scale="0.001 0.001 0.001"/>
      </geometry>
    </collision>
  </link>
  <link name="coxa1_1">
    <inertial>
      <origin rpy="0 0 0" xyz="0.010721348766451672 -0.015867054756867255 -0.03845464138452091"/>
      <mass value="1.0829342534788744"/>
      <inertia ixx="0.000723" ixy="0.000134" ixz="5.9e-05" iyy="0.000615" iyz="-8.7e-05" izz="0.000489"/>
    </inertial>
    <visual>
      <origin rpy="0 0 0" xyz="0.1571 0.05727 -0.0"/>
      <geometry>
        <mesh filename="coxa1_1.stl" scale="0.001 0.001 0.001"/>
      </geometry>
      <material name="silver"/>
    </visual>
    <collision>
      <origin rpy="0 0 0" xyz="0.1571 0.05727 -0.0"/>
      <geometry>
        <mesh filename="coxa1_1.stl" scale="0.001 0.001 0.001"/>
      </geometry>
    </collision>
  </link>
  <link name="coxa2_1">
    <inertial>
      <origin rpy="0 0 0" xyz="0.019149731596684927 -1.7142476112559367e-05 -0.03845464138452086"/>
      <mass value="1.0829342534788744"/>
      <inertia ixx="0.000525" ixy="1e-06" ixz="0.000105" iyy="0.000813" iyz="-0.0" izz="0.000489"/>
    </inertial>
    <visual>
      <origin rpy="0 0 0" xyz="0.152351 -0.0 -0.0"/>
      <geometry>
        <mesh filename="coxa2_1.stl" scale="0.001 0.001 0.001"/>
      </geometry>
      <material name="silver"/>
    </visual>
    <collision>
      <origin rpy="0 0 0" xyz="0.152351 -0.0 -0.0"/>
      <geometry>
        <mesh filename="coxa2_1.stl" scale="0.001 0.001 0.001"/>
      </geometry>
    </collision>
  </link>
  <link name="coxa3_1">
    <inertial>
      <origin rpy="0 0 0" xyz="0.0116175998283789 0.01522303303614854 -0.03845464138452081"/>
      <mass value="1.0829342534788744"/>
      <inertia ixx="0.000707" ixy="-0.000139" ixz="6.4e-05" iyy="0.000631" iyz="8.4e-05" izz="0.000489"/>
    </inertial>
    <visual>
      <origin rpy="0 0 0" xyz="0.1571 -0.05727 -0.0"/>
      <geometry>
        <mesh filename="coxa3_1.stl" scale="0.001 0.001 0.001"/>
      </geometry>
      <material name="silver"/>
    </visual>
    <collision>
      <origin rpy="0 0 0" xyz="0.1571 -0.05727 -0.0"/>
      <geometry>
        <mesh filename="coxa3_1.stl" scale="0.001 0.001 0.001"/>
      </geometry>
    </collision>
  </link>
  <link name="coxa4_1">
    <inertial>
      <origin rpy="0 0 0" xyz="-0.012193322564369419 0.014766371448479601 -0.038454641384520705"/>
      <mass value="1.0829342534788744"/>
      <inertia ixx="0.000697" ixy="0.000142" ixz="-6.7e-05" iyy="0.000641" iyz="8.1e-05" izz="0.000489"/>
    </inertial>
    <visual>
      <origin rpy="0 0 0" xyz="0.237601 -0.05727 -0.0"/>
      <geometry>
        <mesh filename="coxa4_1.stl" scale="0.001 0.001 0.001"/>
      </geometry>
      <material name="silver"/>
    </visual>
    <collision>
      <origin rpy="0 0 0" xyz="0.237601 -0.05727 -0.0"/>
      <geometry>
        <mesh filename="coxa4_1.stl" scale="0.001 0.001 0.001"/>
      </geometry>
    </collision>
  </link>
  <link name="coxa5_1">
    <inertial>
      <origin rpy="0 0 0" xyz="-0.019149322550794573 1.7142476112579354e-05 -0.03845464138452092"/>
      <mass value="1.0829342534788744"/>
      <inertia ixx="0.000525" ixy="1e-06" ixz="-0.000105" iyy="0.000813" iyz="0.0" izz="0.000489"/>
    </inertial>
    <visual>
      <origin rpy="0 0 0" xyz="0.242351 -0.0 -0.0"/>
      <geometry>
        <mesh filename="coxa5_1.stl" scale="0.001 0.001 0.001"/>
      </geometry>
      <material name="silver"/>
    </visual>
    <collision>
      <origin rpy="0 0 0" xyz="0.242351 -0.0 -0.0"/>
      <geometry>
        <mesh filename="coxa5_1.stl" scale="0.001 0.001 0.001"/>
      </geometry>
    </collision>
  </link>
  <link name="coxa6_1">
    <inertial>
      <origin rpy="0 0 0" xyz="-0.011188622468052495 -0.015541492362827966 -0.038454641384520864"/>
      <mass value="1.0829342534788744"/>
      <inertia ixx="0.000715" ixy="-0.000137" ixz="-6.2e-05" iyy="0.000623" iyz="-8.5e-05" izz="0.000489"/>
    </inertial>
    <visual>
      <origin rpy="0 0 0" xyz="0.237601 0.05727 -0.0"/>
      <geometry>
        <mesh filename="coxa6_1.stl" scale="0.001 0.001 0.001"/>
      </geometry>
      <material name="silver"/>
    </visual>
    <collision>
      <origin rpy="0 0 0" xyz="0.237601 0.05727 -0.0"/>
      <geometry>
        <mesh filename="coxa6_1.stl" scale="0.001 0.001 0.001"/>
      </geometry>
    </collision>
  </link>
  <joint name="Revolute 1" type="revolute">
    <origin rpy="0 0 0" xyz="0.012406 -0.047756 -0.0515"/>
    <parent link="coxa1_1"/>
    <child link="teta1_1"/>
    <axis xyz="0.82806 0.560639 0.0"/>
    <limit effort="100" lower="0.0" upper="6.283185" velocity="100"/>
  </joint>
  <joint name="Revolute 2" type="revolute">
    <origin rpy="0 0 0" xyz="0.033639 -0.049683 0.0"/>
    <parent link="teta1_1"/>
    <child link="tibia1_1"/>
    <axis xyz="0.82806 0.560639 -0.0"/>
    <limit effort="100" lower="0.0" upper="6.283185" velocity="100"/>
  </joint>
  <joint name="Revolute 5" type="revolute">
    <origin rpy="0 0 0" xyz="0.0465 -0.0165 -0.0515"/>
    <parent link="coxa2_1"/>
    <child link="teta2_1"/>
    <axis xyz="0.0 -1.0 0.0"/>
    <limit effort="100" lower="0.0" upper="6.283185" velocity="100"/>
  </joint>
  <joint name="Revolute 6" type="revolute">
    <origin rpy="0 0 0" xyz="0.06 0.0 0.0"/>
    <parent link="teta2_1"/>
    <child link="tibia2_1"/>
    <axis xyz="-0.0 1.0 -0.0"/>
    <limit effort="100" lower="0.0" upper="6.283185" velocity="100"/>
  </joint>
  <joint name="Revolute 7" type="revolute">
    <origin rpy="0 0 0" xyz="0.041303 0.026991 -0.0515"/>
    <parent link="coxa3_1"/>
    <child link="teta3_1"/>
    <axis xyz="0.795473 -0.605988 0.0"/>
    <limit effort="100" lower="0.0" upper="6.283185" velocity="100"/>
  </joint>
  <joint name="Revolute 8" type="revolute">
    <origin rpy="0 0 0" xyz="0.03636 0.047729 0.0"/>
    <parent link="teta3_1"/>
    <child link="tibia3_1"/>
    <axis xyz="-0.795473 0.605988 0.0"/>
    <limit effort="100" lower="0.0" upper="6.283185" velocity="100"/>
  </joint>
  <joint name="Revolute 9" type="revolute">
    <origin rpy="0 0 0" xyz="-0.016927 0.046347 -0.0515"/>
    <parent link="coxa4_1"/>
    <child link="teta4_1"/>
    <axis xyz="0.770513 0.637424 0.0"/>
    <limit effort="100" lower="0.0" upper="6.283185" velocity="100"/>
  </joint>
  <joint name="Revolute 10" type="revolute">
    <origin rpy="0 0 0" xyz="-0.038245 0.046231 0.0"/>
    <parent link="teta4_1"/>
    <child link="tibia4_1"/>
    <axis xyz="-0.770513 -0.637424 -0.0"/>
    <limit effort="100" lower="0.0" upper="6.283185" velocity="100"/>
  </joint>
  <joint name="Revolute 11" type="revolute">
    <origin rpy="0 0 0" xyz="-0.0465 0.0165 -0.0515"/>
    <parent link="coxa5_1"/>
    <child link="teta5_1"/>
    <axis xyz="-0.0 1.0 -0.0"/>
    <limit effort="100" lower="0.0" upper="6.283185" velocity="100"/>
  </joint>
  <joint name="Revolute 12" type="revolute">
    <origin rpy="0 0 0" xyz="-0.06 0.0 0.0"/>
    <parent link="teta5_1"/>
    <child link="tibia5_1"/>
    <axis xyz="0.0 -1.0 0.0"/>
    <limit effort="100" lower="0.0" upper="6.283185" velocity="100"/>
  </joint>
  <joint name="Revolute 13" type="revolute">
    <origin rpy="0 0 0" xyz="-0.040534 -0.028134 -0.0515"/>
    <parent link="coxa6_1"/>
    <child link="teta6_1"/>
    <axis xyz="-0.812084 0.583541 0.0"/>
    <limit effort="100" lower="0.0" upper="6.283185" velocity="100"/>
  </joint>
  <joint name="Revolute 14" type="revolute">
    <origin rpy="0 0 0" xyz="-0.035013 -0.048725 0.0"/>
    <parent link="teta6_1"/>
    <child link="tibia6_1"/>
    <axis xyz="0.812084 -0.583541 -0.0"/>
    <limit effort="100" lower="0.0" upper="6.283185" velocity="100"/>
  </joint>
  <joint name="Revolute 15" type="revolute">
    <origin rpy="0 0 0" xyz="-0.1571 -0.05727 0.0"/>
    <parent link="base_link"/>
    <child link="coxa1_1"/>
    <axis xyz="0.0 0.0 1.0"/>
    <limit effort="100" lower="0.0" upper="6.283185" velocity="100"/>
  </joint>
  <joint name="Revolute 16" type="revolute">
    <origin rpy="0 0 0" xyz="-0.152351 0.0 0.0"/>
    <parent link="base_link"/>
    <child link="coxa2_1"/>
    <axis xyz="0.0 0.0 -1.0"/>
    <limit effort="100" lower="0.0" upper="6.283185" velocity="100"/>
  </joint>
  <joint name="Revolute 17" type="revolute">
    <origin rpy="0 0 0" xyz="-0.1571 0.05727 0.0"/>
    <parent link="base_link"/>
    <child link="coxa3_1"/>
    <axis xyz="0.0 0.0 -1.0"/>
    <limit effort="100" lower="0.0" upper="6.283185" velocity="100"/>
  </joint>
  <joint name="Revolute 18" type="revolute">
    <origin rpy="0 0 0" xyz="-0.237601 0.05727 0.0"/>
    <parent link="base_link"/>
    <child link="coxa4_1"/>
    <axis xyz="0.0 0.0 -1.0"/>
    <limit effort="100" lower="0.0" upper="6.283185" velocity="100"/>
  </joint>
  <joint name="Revolute 19" type="revolute">
    <origin rpy="0 0 0" xyz="-0.242351 0.0 0.0"/>
    <parent link="base_link"/>
    <child link="coxa5_1"/>
    <axis xyz="0.0 0.0 -1.0"/>
    <limit effort="100" lower="0.0" upper="6.283185" velocity="100"/>
  </joint>
  <joint name="Revolute 20" type="continuous">
    <origin rpy="0 0 0" xyz="-0.237601 -0.05727 0.0"/>
    <parent link="base_link"/>
    <child link="coxa6_1"/>
    <axis xyz="0.0 0.0 -1.0"/>
  </joint>
</robot>
